INFO     mypy.lib.youtube.y2_downloader:log.py:82 [92müü¢ ÂºÄÂßã‰∏ãËΩΩ„Äähttps://youtube.com/watch?v=peQ-CsY19Ag„Äã[0m
INFO     mypy.lib.youtube.y2_downloader:log.py:82 [92müü¢ ÂºÄÂßã‰∏ãËΩΩ„Äähttps://youtube.com/watch?v=z7bUu-RUcMg„Äã[0m
INFO     mypy.lib.youtube.y2_video_handler:log.py:82 [92müü¢ ===== Ëé∑ÂèñËßÜÈ¢ë =====[0m
INFO     mypy.lib.youtube.y2_video_handler:log.py:82 [92müü¢ ËæìÂá∫Ë∑ØÂæÑ: /home/runner/work/github-runner/github-runner/mypy/tests/lib/youtube/_out/test_y2_downloader/_out/channel_PL-CDIidnoXnBqgBVbf5y9Qm4y4ZKHHYUS[0m
ERROR    mypy.lib.youtube.y2_downloader:log.py:94 [91müî¥ ËßÜÈ¢ë„Äähttps://youtube.com/watch?v=peQ-CsY19Ag„Äã‰∏ãËΩΩÂºÇÂ∏∏: Exception while accessing title of https://youtube.com/watch?v=peQ-CsY19Ag. Please file a bug report at https://github.com/pytube/pytube[0m
Traceback (most recent call last):
  File "/opt/hostedtoolcache/Python/3.9.20/x64/lib/python3.9/site-packages/pytube/__main__.py", line 341, in title
    self._title = self.vid_info['videoDetails']['title']
KeyError: 'videoDetails'

During handling of the above exception, another exception occurred:

Traceback (most recent call last):
  File "/home/runner/work/github-runner/github-runner/mypy/lib/youtube/y2_downloader.py", line 153, in download_video
    api = Y2VideoHandler(work_path=self._work_path,
  File "/home/runner/work/github-runner/github-runner/mypy/lib/youtube/y2_video_handler.py", line 239, in __init__
    self._video_original_title = y2_video.title
  File "/opt/hostedtoolcache/Python/3.9.20/x64/lib/python3.9/site-packages/pytube/__main__.py", line 346, in title
    raise exceptions.PytubeError(
pytube.exceptions.PytubeError: Exception while accessing title of https://youtube.com/watch?v=peQ-CsY19Ag. Please file a bug report at https://github.com/pytube/pytube
ERROR    mypy.lib.youtube.y2_downloader:log.py:94 [91müî¥ ËßÜÈ¢ë„Äähttps://youtube.com/watch?v=z7bUu-RUcMg„Äã‰∏ãËΩΩÂºÇÂ∏∏: ERROR: [youtube] z7bUu-RUcMg: Sign in to confirm you‚Äôre not a bot. This helps protect our community. Learn more[0m
Traceback (most recent call last):
  File "/opt/hostedtoolcache/Python/3.9.20/x64/lib/python3.9/site-packages/yt_dlp/YoutubeDL.py", line 1625, in wrapper
    return func(self, *args, **kwargs)
  File "/opt/hostedtoolcache/Python/3.9.20/x64/lib/python3.9/site-packages/yt_dlp/YoutubeDL.py", line 1760, in __extract_info
    ie_result = ie.extract(url)
  File "/opt/hostedtoolcache/Python/3.9.20/x64/lib/python3.9/site-packages/yt_dlp/extractor/common.py", line 741, in extract
    ie_result = self._real_extract(url)
  File "/opt/hostedtoolcache/Python/3.9.20/x64/lib/python3.9/site-packages/yt_dlp/extractor/youtube.py", line 4671, in _real_extract
    self.raise_no_formats(reason, expected=True)
  File "/opt/hostedtoolcache/Python/3.9.20/x64/lib/python3.9/site-packages/yt_dlp/extractor/common.py", line 1275, in raise_no_formats
    raise ExtractorError(msg, expected=expected, video_id=video_id)
yt_dlp.utils.ExtractorError: [youtube] z7bUu-RUcMg: Sign in to confirm you‚Äôre not a bot. This helps protect our community. Learn more

During handling of the above exception, another exception occurred:

Traceback (most recent call last):
  File "/home/runner/work/github-runner/github-runner/mypy/lib/youtube/y2_downloader.py", line 157, in download_video
    v_title, v_filepath = api.get_video(clean_download=False,
  File "/home/runner/work/github-runner/github-runner/mypy/lib/youtube/y2_video_handler.py", line 292, in get_video
    y2_api = YtdlpHelper(video_url=self._video_url,
  File "/home/runner/work/github-runner/github-runner/mypy/lib/youtube/ytdlp_helper.py", line 75, in __init__
    self._title, self._video_id, self._publish_date = get_video_info(
  File "/home/runner/work/github-runner/github-runner/mypy/lib/youtube/ytdlp_helper.py", line 62, in get_video_info
    info_dict = ydl.extract_info(
  File "/opt/hostedtoolcache/Python/3.9.20/x64/lib/python3.9/site-packages/yt_dlp/YoutubeDL.py", line 1614, in extract_info
    return self.__extract_info(url, self.get_info_extractor(key), download, extra_info, process)
  File "/opt/hostedtoolcache/Python/3.9.20/x64/lib/python3.9/site-packages/yt_dlp/YoutubeDL.py", line 1643, in wrapper
    self.report_error(str(e), e.format_traceback())
  File "/opt/hostedtoolcache/Python/3.9.20/x64/lib/python3.9/site-packages/yt_dlp/YoutubeDL.py", line 1091, in report_error
    self.trouble(f'{self._format_err("ERROR:", self.Styles.ERROR)} {message}', *args, **kwargs)
  File "/opt/hostedtoolcache/Python/3.9.20/x64/lib/python3.9/site-packages/yt_dlp/YoutubeDL.py", line 1030, in trouble
    raise DownloadError(message, exc_info)
yt_dlp.utils.DownloadError: ERROR: [youtube] z7bUu-RUcMg: Sign in to confirm you‚Äôre not a bot. This helps protect our community. Learn more
INFO     mypy.lib.youtube.y2_downloader:log.py:82 [92müü¢ ÂºÄÂßã‰∏ãËΩΩ„Äähttps://youtube.com/watch?v=peQ-CsY19Ag„Äã[0m
INFO     mypy.lib.youtube.y2_video_handler:log.py:82 [92müü¢ ===== Ëé∑ÂèñËßÜÈ¢ë =====[0m
INFO     mypy.lib.youtube.y2_video_handler:log.py:82 [92müü¢ ËæìÂá∫Ë∑ØÂæÑ: /home/runner/work/github-runner/github-runner/mypy/tests/lib/youtube/_out/test_y2_downloader/_out/channel_PL-CDIidnoXnBqgBVbf5y9Qm4y4ZKHHYUS[0m
INFO     mypy.lib.youtube.y2_downloader:log.py:82 [92müü¢ ÂºÄÂßã‰∏ãËΩΩ„Äähttps://youtube.com/watch?v=z7bUu-RUcMg„Äã[0m
ERROR    mypy.lib.youtube.y2_downloader:log.py:94 [91müî¥ ËßÜÈ¢ë„Äähttps://youtube.com/watch?v=z7bUu-RUcMg„Äã‰∏ãËΩΩÂºÇÂ∏∏: Exception while accessing title of https://youtube.com/watch?v=z7bUu-RUcMg. Please file a bug report at https://github.com/pytube/pytube[0m
Traceback (most recent call last):
  File "/opt/hostedtoolcache/Python/3.9.20/x64/lib/python3.9/site-packages/pytube/__main__.py", line 341, in title
    self._title = self.vid_info['videoDetails']['title']
KeyError: 'videoDetails'

During handling of the above exception, another exception occurred:

Traceback (most recent call last):
  File "/home/runner/work/github-runner/github-runner/mypy/lib/youtube/y2_downloader.py", line 153, in download_video
    api = Y2VideoHandler(work_path=self._work_path,
  File "/home/runner/work/github-runner/github-runner/mypy/lib/youtube/y2_video_handler.py", line 239, in __init__
    self._video_original_title = y2_video.title
  File "/opt/hostedtoolcache/Python/3.9.20/x64/lib/python3.9/site-packages/pytube/__main__.py", line 346, in title
    raise exceptions.PytubeError(
pytube.exceptions.PytubeError: Exception while accessing title of https://youtube.com/watch?v=z7bUu-RUcMg. Please file a bug report at https://github.com/pytube/pytube
ERROR    mypy.lib.youtube.y2_downloader:log.py:94 [91müî¥ ËßÜÈ¢ë„Äähttps://youtube.com/watch?v=peQ-CsY19Ag„Äã‰∏ãËΩΩÂºÇÂ∏∏: ERROR: [youtube] peQ-CsY19Ag: Sign in to confirm you‚Äôre not a bot. This helps protect our community. Learn more[0m
Traceback (most recent call last):
  File "/opt/hostedtoolcache/Python/3.9.20/x64/lib/python3.9/site-packages/yt_dlp/YoutubeDL.py", line 1625, in wrapper
    return func(self, *args, **kwargs)
  File "/opt/hostedtoolcache/Python/3.9.20/x64/lib/python3.9/site-packages/yt_dlp/YoutubeDL.py", line 1760, in __extract_info
    ie_result = ie.extract(url)
  File "/opt/hostedtoolcache/Python/3.9.20/x64/lib/python3.9/site-packages/yt_dlp/extractor/common.py", line 741, in extract
    ie_result = self._real_extract(url)
  File "/opt/hostedtoolcache/Python/3.9.20/x64/lib/python3.9/site-packages/yt_dlp/extractor/youtube.py", line 4671, in _real_extract
    self.raise_no_formats(reason, expected=True)
  File "/opt/hostedtoolcache/Python/3.9.20/x64/lib/python3.9/site-packages/yt_dlp/extractor/common.py", line 1275, in raise_no_formats
    raise ExtractorError(msg, expected=expected, video_id=video_id)
yt_dlp.utils.ExtractorError: [youtube] peQ-CsY19Ag: Sign in to confirm you‚Äôre not a bot. This helps protect our community. Learn more

During handling of the above exception, another exception occurred:

Traceback (most recent call last):
  File "/home/runner/work/github-runner/github-runner/mypy/lib/youtube/y2_downloader.py", line 157, in download_video
    v_title, v_filepath = api.get_video(clean_download=False,
  File "/home/runner/work/github-runner/github-runner/mypy/lib/youtube/y2_video_handler.py", line 292, in get_video
    y2_api = YtdlpHelper(video_url=self._video_url,
  File "/home/runner/work/github-runner/github-runner/mypy/lib/youtube/ytdlp_helper.py", line 75, in __init__
    self._title, self._video_id, self._publish_date = get_video_info(
  File "/home/runner/work/github-runner/github-runner/mypy/lib/youtube/ytdlp_helper.py", line 62, in get_video_info
    info_dict = ydl.extract_info(
  File "/opt/hostedtoolcache/Python/3.9.20/x64/lib/python3.9/site-packages/yt_dlp/YoutubeDL.py", line 1614, in extract_info
    return self.__extract_info(url, self.get_info_extractor(key), download, extra_info, process)
  File "/opt/hostedtoolcache/Python/3.9.20/x64/lib/python3.9/site-packages/yt_dlp/YoutubeDL.py", line 1643, in wrapper
    self.report_error(str(e), e.format_traceback())
  File "/opt/hostedtoolcache/Python/3.9.20/x64/lib/python3.9/site-packages/yt_dlp/YoutubeDL.py", line 1091, in report_error
    self.trouble(f'{self._format_err("ERROR:", self.Styles.ERROR)} {message}', *args, **kwargs)
  File "/opt/hostedtoolcache/Python/3.9.20/x64/lib/python3.9/site-packages/yt_dlp/YoutubeDL.py", line 1030, in trouble
    raise DownloadError(message, exc_info)
yt_dlp.utils.DownloadError: ERROR: [youtube] peQ-CsY19Ag: Sign in to confirm you‚Äôre not a bot. This helps protect our community. Learn more
INFO     mypy.lib.youtube.y2_downloader:log.py:82 [92müü¢ ÂºÄÂßã‰∏ãËΩΩ„Äähttps://youtube.com/watch?v=z7bUu-RUcMg„Äã[0m
INFO     mypy.lib.youtube.y2_downloader:log.py:82 [92müü¢ ÂºÄÂßã‰∏ãËΩΩ„Äähttps://youtube.com/watch?v=peQ-CsY19Ag„Äã[0m
ERROR    mypy.lib.youtube.y2_downloader:log.py:94 [91müî¥ ËßÜÈ¢ë„Äähttps://youtube.com/watch?v=z7bUu-RUcMg„Äã‰∏ãËΩΩÂºÇÂ∏∏: Exception while accessing title of https://youtube.com/watch?v=z7bUu-RUcMg. Please file a bug report at https://github.com/pytube/pytube[0m
Traceback (most recent call last):
  File "/opt/hostedtoolcache/Python/3.9.20/x64/lib/python3.9/site-packages/pytube/__main__.py", line 341, in title
    self._title = self.vid_info['videoDetails']['title']
KeyError: 'videoDetails'

During handling of the above exception, another exception occurred:

Traceback (most recent call last):
  File "/home/runner/work/github-runner/github-runner/mypy/lib/youtube/y2_downloader.py", line 153, in download_video
    api = Y2VideoHandler(work_path=self._work_path,
  File "/home/runner/work/github-runner/github-runner/mypy/lib/youtube/y2_video_handler.py", line 239, in __init__
    self._video_original_title = y2_video.title
  File "/opt/hostedtoolcache/Python/3.9.20/x64/lib/python3.9/site-packages/pytube/__main__.py", line 346, in title
    raise exceptions.PytubeError(
pytube.exceptions.PytubeError: Exception while accessing title of https://youtube.com/watch?v=z7bUu-RUcMg. Please file a bug report at https://github.com/pytube/pytube
ERROR    mypy.lib.youtube.y2_downloader:log.py:94 [91müî¥ ËßÜÈ¢ë„Äähttps://youtube.com/watch?v=peQ-CsY19Ag„Äã‰∏ãËΩΩÂºÇÂ∏∏: Exception while accessing title of https://youtube.com/watch?v=peQ-CsY19Ag. Please file a bug report at https://github.com/pytube/pytube[0m
Traceback (most recent call last):
  File "/opt/hostedtoolcache/Python/3.9.20/x64/lib/python3.9/site-packages/pytube/__main__.py", line 341, in title
    self._title = self.vid_info['videoDetails']['title']
KeyError: 'videoDetails'

During handling of the above exception, another exception occurred:

Traceback (most recent call last):
  File "/home/runner/work/github-runner/github-runner/mypy/lib/youtube/y2_downloader.py", line 153, in download_video
    api = Y2VideoHandler(work_path=self._work_path,
  File "/home/runner/work/github-runner/github-runner/mypy/lib/youtube/y2_video_handler.py", line 239, in __init__
    self._video_original_title = y2_video.title
  File "/opt/hostedtoolcache/Python/3.9.20/x64/lib/python3.9/site-packages/pytube/__main__.py", line 346, in title
    raise exceptions.PytubeError(
pytube.exceptions.PytubeError: Exception while accessing title of https://youtube.com/watch?v=peQ-CsY19Ag. Please file a bug report at https://github.com/pytube/pytube
INFO     mypy.lib.youtube.y2_downloader:log.py:82 [92müü¢ ÂºÄÂßã‰∏ãËΩΩ„Äähttps://youtube.com/watch?v=z7bUu-RUcMg„Äã[0m
INFO     mypy.lib.youtube.y2_downloader:log.py:82 [92müü¢ ÂºÄÂßã‰∏ãËΩΩ„Äähttps://youtube.com/watch?v=peQ-CsY19Ag„Äã[0m
INFO     mypy.lib.youtube.y2_video_handler:log.py:82 [92müü¢ ===== Ëé∑ÂèñËßÜÈ¢ë =====[0m
INFO     mypy.lib.youtube.y2_video_handler:log.py:82 [92müü¢ ËæìÂá∫Ë∑ØÂæÑ: /home/runner/work/github-runner/github-runner/mypy/tests/lib/youtube/_out/test_y2_downloader/_out/channel_PL-CDIidnoXnBqgBVbf5y9Qm4y4ZKHHYUS[0m
ERROR    mypy.lib.youtube.y2_downloader:log.py:94 [91müî¥ ËßÜÈ¢ë„Äähttps://youtube.com/watch?v=peQ-CsY19Ag„Äã‰∏ãËΩΩÂºÇÂ∏∏: Exception while accessing title of https://youtube.com/watch?v=peQ-CsY19Ag. Please file a bug report at https://github.com/pytube/pytube[0m
Traceback (most recent call last):
  File "/opt/hostedtoolcache/Python/3.9.20/x64/lib/python3.9/site-packages/pytube/__main__.py", line 341, in title
    self._title = self.vid_info['videoDetails']['title']
KeyError: 'videoDetails'

During handling of the above exception, another exception occurred:

Traceback (most recent call last):
  File "/home/runner/work/github-runner/github-runner/mypy/lib/youtube/y2_downloader.py", line 153, in download_video
    api = Y2VideoHandler(work_path=self._work_path,
  File "/home/runner/work/github-runner/github-runner/mypy/lib/youtube/y2_video_handler.py", line 239, in __init__
    self._video_original_title = y2_video.title
  File "/opt/hostedtoolcache/Python/3.9.20/x64/lib/python3.9/site-packages/pytube/__main__.py", line 346, in title
    raise exceptions.PytubeError(
pytube.exceptions.PytubeError: Exception while accessing title of https://youtube.com/watch?v=peQ-CsY19Ag. Please file a bug report at https://github.com/pytube/pytube
ERROR    mypy.lib.youtube.y2_downloader:log.py:94 [91müî¥ ËßÜÈ¢ë„Äähttps://youtube.com/watch?v=z7bUu-RUcMg„Äã‰∏ãËΩΩÂºÇÂ∏∏: ERROR: [youtube] z7bUu-RUcMg: Sign in to confirm you‚Äôre not a bot. This helps protect our community. Learn more[0m
Traceback (most recent call last):
  File "/opt/hostedtoolcache/Python/3.9.20/x64/lib/python3.9/site-packages/yt_dlp/YoutubeDL.py", line 1625, in wrapper
    return func(self, *args, **kwargs)
  File "/opt/hostedtoolcache/Python/3.9.20/x64/lib/python3.9/site-packages/yt_dlp/YoutubeDL.py", line 1760, in __extract_info
    ie_result = ie.extract(url)
  File "/opt/hostedtoolcache/Python/3.9.20/x64/lib/python3.9/site-packages/yt_dlp/extractor/common.py", line 741, in extract
    ie_result = self._real_extract(url)
  File "/opt/hostedtoolcache/Python/3.9.20/x64/lib/python3.9/site-packages/yt_dlp/extractor/youtube.py", line 4671, in _real_extract
    self.raise_no_formats(reason, expected=True)
  File "/opt/hostedtoolcache/Python/3.9.20/x64/lib/python3.9/site-packages/yt_dlp/extractor/common.py", line 1275, in raise_no_formats
    raise ExtractorError(msg, expected=expected, video_id=video_id)
yt_dlp.utils.ExtractorError: [youtube] z7bUu-RUcMg: Sign in to confirm you‚Äôre not a bot. This helps protect our community. Learn more

During handling of the above exception, another exception occurred:

Traceback (most recent call last):
  File "/home/runner/work/github-runner/github-runner/mypy/lib/youtube/y2_downloader.py", line 157, in download_video
    v_title, v_filepath = api.get_video(clean_download=False,
  File "/home/runner/work/github-runner/github-runner/mypy/lib/youtube/y2_video_handler.py", line 292, in get_video
    y2_api = YtdlpHelper(video_url=self._video_url,
  File "/home/runner/work/github-runner/github-runner/mypy/lib/youtube/ytdlp_helper.py", line 75, in __init__
    self._title, self._video_id, self._publish_date = get_video_info(
  File "/home/runner/work/github-runner/github-runner/mypy/lib/youtube/ytdlp_helper.py", line 62, in get_video_info
    info_dict = ydl.extract_info(
  File "/opt/hostedtoolcache/Python/3.9.20/x64/lib/python3.9/site-packages/yt_dlp/YoutubeDL.py", line 1614, in extract_info
    return self.__extract_info(url, self.get_info_extractor(key), download, extra_info, process)
  File "/opt/hostedtoolcache/Python/3.9.20/x64/lib/python3.9/site-packages/yt_dlp/YoutubeDL.py", line 1643, in wrapper
    self.report_error(str(e), e.format_traceback())
  File "/opt/hostedtoolcache/Python/3.9.20/x64/lib/python3.9/site-packages/yt_dlp/YoutubeDL.py", line 1091, in report_error
    self.trouble(f'{self._format_err("ERROR:", self.Styles.ERROR)} {message}', *args, **kwargs)
  File "/opt/hostedtoolcache/Python/3.9.20/x64/lib/python3.9/site-packages/yt_dlp/YoutubeDL.py", line 1030, in trouble
    raise DownloadError(message, exc_info)
yt_dlp.utils.DownloadError: ERROR: [youtube] z7bUu-RUcMg: Sign in to confirm you‚Äôre not a bot. This helps protect our community. Learn more
INFO     mypy.lib.youtube.y2_downloader:log.py:82 [92müü¢ ÂºÄÂßã‰∏ãËΩΩ„Äähttps://youtube.com/watch?v=peQ-CsY19Ag„Äã[0m
INFO     mypy.lib.youtube.y2_video_handler:log.py:82 [92müü¢ ===== Ëé∑ÂèñËßÜÈ¢ë =====[0m
INFO     mypy.lib.youtube.y2_video_handler:log.py:82 [92müü¢ ËæìÂá∫Ë∑ØÂæÑ: /home/runner/work/github-runner/github-runner/mypy/tests/lib/youtube/_out/test_y2_downloader/_out/channel_PL-CDIidnoXnBqgBVbf5y9Qm4y4ZKHHYUS[0m
INFO     mypy.lib.youtube.y2_downloader:log.py:82 [92müü¢ ÂºÄÂßã‰∏ãËΩΩ„Äähttps://youtube.com/watch?v=z7bUu-RUcMg„Äã[0m
ERROR    mypy.lib.youtube.y2_downloader:log.py:94 [91müî¥ ËßÜÈ¢ë„Äähttps://youtube.com/watch?v=peQ-CsY19Ag„Äã‰∏ãËΩΩÂºÇÂ∏∏: ERROR: [youtube] peQ-CsY19Ag: Sign in to confirm you‚Äôre not a bot. This helps protect our community. Learn more[0m
Traceback (most recent call last):
  File "/opt/hostedtoolcache/Python/3.9.20/x64/lib/python3.9/site-packages/yt_dlp/YoutubeDL.py", line 1625, in wrapper
    return func(self, *args, **kwargs)
  File "/opt/hostedtoolcache/Python/3.9.20/x64/lib/python3.9/site-packages/yt_dlp/YoutubeDL.py", line 1760, in __extract_info
    ie_result = ie.extract(url)
  File "/opt/hostedtoolcache/Python/3.9.20/x64/lib/python3.9/site-packages/yt_dlp/extractor/common.py", line 741, in extract
    ie_result = self._real_extract(url)
  File "/opt/hostedtoolcache/Python/3.9.20/x64/lib/python3.9/site-packages/yt_dlp/extractor/youtube.py", line 4671, in _real_extract
    self.raise_no_formats(reason, expected=True)
  File "/opt/hostedtoolcache/Python/3.9.20/x64/lib/python3.9/site-packages/yt_dlp/extractor/common.py", line 1275, in raise_no_formats
    raise ExtractorError(msg, expected=expected, video_id=video_id)
yt_dlp.utils.ExtractorError: [youtube] peQ-CsY19Ag: Sign in to confirm you‚Äôre not a bot. This helps protect our community. Learn more

During handling of the above exception, another exception occurred:

Traceback (most recent call last):
  File "/home/runner/work/github-runner/github-runner/mypy/lib/youtube/y2_downloader.py", line 157, in download_video
    v_title, v_filepath = api.get_video(clean_download=False,
  File "/home/runner/work/github-runner/github-runner/mypy/lib/youtube/y2_video_handler.py", line 292, in get_video
    y2_api = YtdlpHelper(video_url=self._video_url,
  File "/home/runner/work/github-runner/github-runner/mypy/lib/youtube/ytdlp_helper.py", line 75, in __init__
    self._title, self._video_id, self._publish_date = get_video_info(
  File "/home/runner/work/github-runner/github-runner/mypy/lib/youtube/ytdlp_helper.py", line 62, in get_video_info
    info_dict = ydl.extract_info(
  File "/opt/hostedtoolcache/Python/3.9.20/x64/lib/python3.9/site-packages/yt_dlp/YoutubeDL.py", line 1614, in extract_info
    return self.__extract_info(url, self.get_info_extractor(key), download, extra_info, process)
  File "/opt/hostedtoolcache/Python/3.9.20/x64/lib/python3.9/site-packages/yt_dlp/YoutubeDL.py", line 1643, in wrapper
    self.report_error(str(e), e.format_traceback())
  File "/opt/hostedtoolcache/Python/3.9.20/x64/lib/python3.9/site-packages/yt_dlp/YoutubeDL.py", line 1091, in report_error
    self.trouble(f'{self._format_err("ERROR:", self.Styles.ERROR)} {message}', *args, **kwargs)
  File "/opt/hostedtoolcache/Python/3.9.20/x64/lib/python3.9/site-packages/yt_dlp/YoutubeDL.py", line 1030, in trouble
    raise DownloadError(message, exc_info)
yt_dlp.utils.DownloadError: ERROR: [youtube] peQ-CsY19Ag: Sign in to confirm you‚Äôre not a bot. This helps protect our community. Learn more
ERROR    mypy.lib.youtube.y2_downloader:log.py:94 [91müî¥ ËßÜÈ¢ë„Äähttps://youtube.com/watch?v=z7bUu-RUcMg„Äã‰∏ãËΩΩÂºÇÂ∏∏: Exception while accessing title of https://youtube.com/watch?v=z7bUu-RUcMg. Please file a bug report at https://github.com/pytube/pytube[0m
Traceback (most recent call last):
  File "/opt/hostedtoolcache/Python/3.9.20/x64/lib/python3.9/site-packages/pytube/__main__.py", line 341, in title
    self._title = self.vid_info['videoDetails']['title']
KeyError: 'videoDetails'

During handling of the above exception, another exception occurred:

Traceback (most recent call last):
  File "/home/runner/work/github-runner/github-runner/mypy/lib/youtube/y2_downloader.py", line 153, in download_video
    api = Y2VideoHandler(work_path=self._work_path,
  File "/home/runner/work/github-runner/github-runner/mypy/lib/youtube/y2_video_handler.py", line 239, in __init__
    self._video_original_title = y2_video.title
  File "/opt/hostedtoolcache/Python/3.9.20/x64/lib/python3.9/site-packages/pytube/__main__.py", line 346, in title
    raise exceptions.PytubeError(
pytube.exceptions.PytubeError: Exception while accessing title of https://youtube.com/watch?v=z7bUu-RUcMg. Please file a bug report at https://github.com/pytube/pytube