INFO     conftest:conftest.py:117 ðŸŸ¢ [åˆ›å»º]æµ‹è¯•ç”¨ä¾‹è¾“å‡ºç›®å½•: /home/runner/work/github-runner/github-runner/mypy/tests/lib/youtube/_out/test_y2_downloader
ERROR    mypy.lib.youtube.y2_downloader:y2_downloader.py:182 ðŸ”´ è§†é¢‘ã€Šhttps://www.youtube.com/watch?v=0AVrZ5tw_SMã€‹ä¸‹è½½å¼‚å¸¸: unsupported operand type(s) for +: 'NoneType' and 'str'
Traceback (most recent call last):
  File "/home/runner/work/github-runner/github-runner/mypy/lib/youtube/y2_downloader.py", line 144, in download_video
    if self._is_video_downloaded(channel_id, video_url):
  File "/home/runner/work/github-runner/github-runner/mypy/lib/youtube/y2_downloader.py", line 111, in _is_video_downloaded
    self._config_dir, channel_id + '.json')
TypeError: unsupported operand type(s) for +: 'NoneType' and 'str'
ERROR    mypy.lib.youtube.y2_downloader:y2_downloader.py:182 ðŸ”´ è§†é¢‘ã€Šhttps://www.youtube.com/watch?v=0AVrZ5tw_SMã€‹ä¸‹è½½å¼‚å¸¸: unsupported operand type(s) for +: 'NoneType' and 'str'
Traceback (most recent call last):
  File "/home/runner/work/github-runner/github-runner/mypy/lib/youtube/y2_downloader.py", line 144, in download_video
    if self._is_video_downloaded(channel_id, video_url):
  File "/home/runner/work/github-runner/github-runner/mypy/lib/youtube/y2_downloader.py", line 111, in _is_video_downloaded
    self._config_dir, channel_id + '.json')
TypeError: unsupported operand type(s) for +: 'NoneType' and 'str'
INFO     mypy.lib.youtube.y2_downloader:y2_downloader.py:152 ðŸŸ¢ å¼€å§‹ä¸‹è½½ã€Šhttps://www.youtube.com/watch?v=0AVrZ5tw_SMã€‹
ERROR    mypy.lib.youtube.y2_downloader:y2_downloader.py:182 ðŸ”´ è§†é¢‘ã€Šhttps://www.youtube.com/watch?v=0AVrZ5tw_SMã€‹ä¸‹è½½å¼‚å¸¸: Exception while accessing title of https://youtube.com/watch?v=0AVrZ5tw_SM. Please file a bug report at https://github.com/pytube/pytube
Traceback (most recent call last):
  File "/opt/hostedtoolcache/Python/3.9.19/x64/lib/python3.9/site-packages/pytube/__main__.py", line 341, in title
    self._title = self.vid_info['videoDetails']['title']
KeyError: 'videoDetails'

During handling of the above exception, another exception occurred:

Traceback (most recent call last):
  File "/home/runner/work/github-runner/github-runner/mypy/lib/youtube/y2_downloader.py", line 153, in download_video
    api = Y2VideoHandler(work_path=self._work_path,
  File "/home/runner/work/github-runner/github-runner/mypy/lib/youtube/y2_video_handler.py", line 239, in __init__
    self._video_original_title = y2_video.title
  File "/opt/hostedtoolcache/Python/3.9.19/x64/lib/python3.9/site-packages/pytube/__main__.py", line 346, in title
    raise exceptions.PytubeError(
pytube.exceptions.PytubeError: Exception while accessing title of https://youtube.com/watch?v=0AVrZ5tw_SM. Please file a bug report at https://github.com/pytube/pytube
ERROR    mypy.lib.youtube.y2_downloader:y2_downloader.py:182 ðŸ”´ è§†é¢‘ã€Šhttps://www.youtube.com/watch?v=0AVrZ5tw_SMã€‹ä¸‹è½½å¼‚å¸¸: unsupported operand type(s) for +: 'NoneType' and 'str'
Traceback (most recent call last):
  File "/home/runner/work/github-runner/github-runner/mypy/lib/youtube/y2_downloader.py", line 144, in download_video
    if self._is_video_downloaded(channel_id, video_url):
  File "/home/runner/work/github-runner/github-runner/mypy/lib/youtube/y2_downloader.py", line 111, in _is_video_downloaded
    self._config_dir, channel_id + '.json')
TypeError: unsupported operand type(s) for +: 'NoneType' and 'str'
INFO     mypy.lib.youtube.y2_downloader:y2_downloader.py:152 ðŸŸ¢ å¼€å§‹ä¸‹è½½ã€Šhttps://www.youtube.com/watch?v=0AVrZ5tw_SMã€‹
ERROR    mypy.lib.youtube.y2_downloader:y2_downloader.py:182 ðŸ”´ è§†é¢‘ã€Šhttps://www.youtube.com/watch?v=0AVrZ5tw_SMã€‹ä¸‹è½½å¼‚å¸¸: Exception while accessing title of https://youtube.com/watch?v=0AVrZ5tw_SM. Please file a bug report at https://github.com/pytube/pytube
Traceback (most recent call last):
  File "/opt/hostedtoolcache/Python/3.9.19/x64/lib/python3.9/site-packages/pytube/__main__.py", line 341, in title
    self._title = self.vid_info['videoDetails']['title']
KeyError: 'videoDetails'

During handling of the above exception, another exception occurred:

Traceback (most recent call last):
  File "/home/runner/work/github-runner/github-runner/mypy/lib/youtube/y2_downloader.py", line 153, in download_video
    api = Y2VideoHandler(work_path=self._work_path,
  File "/home/runner/work/github-runner/github-runner/mypy/lib/youtube/y2_video_handler.py", line 239, in __init__
    self._video_original_title = y2_video.title
  File "/opt/hostedtoolcache/Python/3.9.19/x64/lib/python3.9/site-packages/pytube/__main__.py", line 346, in title
    raise exceptions.PytubeError(
pytube.exceptions.PytubeError: Exception while accessing title of https://youtube.com/watch?v=0AVrZ5tw_SM. Please file a bug report at https://github.com/pytube/pytube