INFO     mypy.lib.wechat.video.publish_app:publish_app.py:123 üü¢ ÈªòËÆ§ÈÄâÊã©Á¨¨‰∏Ä‰∏™ cookie: /home/runner/work/github-runner/github-runner/mypy/tests/lib/wechat/config/cookie/wechat/cookie_large.json
INFO     mypy.lib.playwright.publish_config:publish_config.py:122 üü¢ -----> ÈÖçÁΩÆÂ¶Ç‰∏ã <-----
INFO     mypy.lib.wechat.video.publish_app:publish_app.py:139 üü¢ ‰ªéÈÖçÁΩÆÊñá‰ª∂‰∏≠ËØªÂèñÁöÑÂèëÂ∏ÉË¥¶Âè∑: /home/runner/work/github-runner/github-runner/mypy/tests/lib/wechat/config/cookie/wechat/cookie_large.json
INFO     mypy.lib.wechat.video.publish_app:publish_app.py:156 üü¢ Ê≠£Âú®‰ΩøÁî® [/home/runner/work/github-runner/github-runner/mypy/tests/lib/wechat/config/cookie/wechat/cookie_large.json] ÂèëÂ∏É‰ΩúÂìÅ
WARNING  mypy.lib.wechat.video.publish_app:publish_helper.py:48 üü† Ëé∑Âèñ‰ª£ÁêÜÂ§±Ë¥•: HTTPConnectionPool(host='127.0.0.1', port=5010): Max retries exceeded with url: /all?type=https (Caused by NewConnectionError('<urllib3.connection.HTTPConnection object at 0x7f7f9ff16d60>: Failed to establish a new connection: [Errno 111] Connection refused'))
DEBUG    mypy.lib.wechat.video.publish_app:publish_helper.py:59 üîµ ‰ªéÊñá‰ª∂Ê†áÈ¢òËß£ÊûêÂá∫ËØùÈ¢ò: #ppt #video #maked
INFO     mypy.lib.wechat.video.publish_app:publish_helper.py:132 üü¢ ============================================================
INFO     mypy.lib.wechat.video.publish_app:publish_helper.py:133 üü¢ [WechatPublishHelper] ÂºÄÂßãÊâßË°åÂèëÂ∏É‰ªªÂä°
INFO     mypy.lib.wechat.video.publish_app:publish_helper.py:134 üü¢ ============================================================
ERROR    mypy.lib.wechat.video.publish_app:publish_helper.py:97 üî¥ Ë¥¶Âè∑ÁôªÂΩïÁä∂ÊÄÅÂ∑≤Â§±ÊïàÔºåÊ≠£Âú®Ë∑≥Âá∫: Page.inner_text: Timeout 120000ms exceeded.
Call log:
waiting for locator(".finder-nickname")
Traceback (most recent call last):
  File "/home/runner/work/github-runner/github-runner/mypy/lib/playwright/core/publish_helper.py", line 94, in _check_login_status
    user_name = await self._get_logined_username(page)
  File "/home/runner/work/github-runner/github-runner/mypy/lib/playwright/core/publish_helper.py", line 85, in _get_logined_username
    raise ex
  File "/home/runner/work/github-runner/github-runner/mypy/lib/playwright/core/publish_helper.py", line 81, in _get_logined_username
    user_name = await page.inner_text(
  File "/opt/hostedtoolcache/Python/3.9.19/x64/lib/python3.9/site-packages/playwright/async_api/_generated.py", line 10493, in inner_text
    await self._impl_obj.inner_text(
  File "/opt/hostedtoolcache/Python/3.9.19/x64/lib/python3.9/site-packages/playwright/_impl/_page.py", line 904, in inner_text
    return await self._main_frame.inner_text(**locals_to_params(locals()))
  File "/opt/hostedtoolcache/Python/3.9.19/x64/lib/python3.9/site-packages/playwright/_impl/_frame.py", line 618, in inner_text
    return await self._channel.send("innerText", locals_to_params(locals()))
  File "/opt/hostedtoolcache/Python/3.9.19/x64/lib/python3.9/site-packages/playwright/_impl/_connection.py", line 59, in send
    return await self._connection.wrap_api_call(
  File "/opt/hostedtoolcache/Python/3.9.19/x64/lib/python3.9/site-packages/playwright/_impl/_connection.py", line 514, in wrap_api_call
    raise rewrite_error(error, f"{parsed_st['apiName']}: {error}") from None
playwright._impl._errors.TimeoutError: Page.inner_text: Timeout 120000ms exceeded.
Call log:
waiting for locator(".finder-nickname")

ERROR    mypy.lib.wechat.video.publish_app:publish_helper.py:160 üî¥ „Ääppt_video_maked„ÄãÂèëÂ∏ÉÂºÇÂ∏∏: Page.inner_text: Timeout 120000ms exceeded.
Call log:
waiting for locator(".finder-nickname")
Traceback (most recent call last):
  File "/home/runner/work/github-runner/github-runner/mypy/lib/playwright/core/publish_helper.py", line 94, in _check_login_status
    user_name = await self._get_logined_username(page)
  File "/home/runner/work/github-runner/github-runner/mypy/lib/playwright/core/publish_helper.py", line 85, in _get_logined_username
    raise ex
  File "/home/runner/work/github-runner/github-runner/mypy/lib/playwright/core/publish_helper.py", line 81, in _get_logined_username
    user_name = await page.inner_text(
  File "/opt/hostedtoolcache/Python/3.9.19/x64/lib/python3.9/site-packages/playwright/async_api/_generated.py", line 10493, in inner_text
    await self._impl_obj.inner_text(
  File "/opt/hostedtoolcache/Python/3.9.19/x64/lib/python3.9/site-packages/playwright/_impl/_page.py", line 904, in inner_text
    return await self._main_frame.inner_text(**locals_to_params(locals()))
  File "/opt/hostedtoolcache/Python/3.9.19/x64/lib/python3.9/site-packages/playwright/_impl/_frame.py", line 618, in inner_text
    return await self._channel.send("innerText", locals_to_params(locals()))
  File "/opt/hostedtoolcache/Python/3.9.19/x64/lib/python3.9/site-packages/playwright/_impl/_connection.py", line 59, in send
    return await self._connection.wrap_api_call(
  File "/opt/hostedtoolcache/Python/3.9.19/x64/lib/python3.9/site-packages/playwright/_impl/_connection.py", line 514, in wrap_api_call
    raise rewrite_error(error, f"{parsed_st['apiName']}: {error}") from None
playwright._impl._errors.TimeoutError: Page.inner_text: Timeout 120000ms exceeded.
Call log:
waiting for locator(".finder-nickname")


The above exception was the direct cause of the following exception:

Traceback (most recent call last):
  File "/home/runner/work/github-runner/github-runner/mypy/lib/playwright/core/publish_helper.py", line 145, in publish_mission
    await self._check_login_status(page)
  File "/home/runner/work/github-runner/github-runner/mypy/lib/playwright/core/publish_helper.py", line 98, in _check_login_status
    raise CheckLoginStatusExp(original_exception=ex) from ex
mypy.lib.playwright.exceptions.CheckLoginStatusExp: Page.inner_text: Timeout 120000ms exceeded.
Call log:
waiting for locator(".finder-nickname")

ERROR    mypy.lib.playwright.common:common.py:141 üî¥ Page.inner_text: Timeout 120000ms exceeded.
Call log:
waiting for locator(".finder-nickname")
Traceback (most recent call last):
  File "/home/runner/work/github-runner/github-runner/mypy/lib/playwright/core/publish_helper.py", line 94, in _check_login_status
    user_name = await self._get_logined_username(page)
  File "/home/runner/work/github-runner/github-runner/mypy/lib/playwright/core/publish_helper.py", line 85, in _get_logined_username
    raise ex
  File "/home/runner/work/github-runner/github-runner/mypy/lib/playwright/core/publish_helper.py", line 81, in _get_logined_username
    user_name = await page.inner_text(
  File "/opt/hostedtoolcache/Python/3.9.19/x64/lib/python3.9/site-packages/playwright/async_api/_generated.py", line 10493, in inner_text
    await self._impl_obj.inner_text(
  File "/opt/hostedtoolcache/Python/3.9.19/x64/lib/python3.9/site-packages/playwright/_impl/_page.py", line 904, in inner_text
    return await self._main_frame.inner_text(**locals_to_params(locals()))
  File "/opt/hostedtoolcache/Python/3.9.19/x64/lib/python3.9/site-packages/playwright/_impl/_frame.py", line 618, in inner_text
    return await self._channel.send("innerText", locals_to_params(locals()))
  File "/opt/hostedtoolcache/Python/3.9.19/x64/lib/python3.9/site-packages/playwright/_impl/_connection.py", line 59, in send
    return await self._connection.wrap_api_call(
  File "/opt/hostedtoolcache/Python/3.9.19/x64/lib/python3.9/site-packages/playwright/_impl/_connection.py", line 514, in wrap_api_call
    raise rewrite_error(error, f"{parsed_st['apiName']}: {error}") from None
playwright._impl._errors.TimeoutError: Page.inner_text: Timeout 120000ms exceeded.
Call log:
waiting for locator(".finder-nickname")


The above exception was the direct cause of the following exception:

Traceback (most recent call last):
  File "/home/runner/work/github-runner/github-runner/mypy/lib/playwright/common.py", line 139, in launch_browser_mgr
    yield browser, context, page
  File "/home/runner/work/github-runner/github-runner/mypy/lib/playwright/core/publish_helper.py", line 161, in publish_mission
    raise ex
  File "/home/runner/work/github-runner/github-runner/mypy/lib/playwright/core/publish_helper.py", line 145, in publish_mission
    await self._check_login_status(page)
  File "/home/runner/work/github-runner/github-runner/mypy/lib/playwright/core/publish_helper.py", line 98, in _check_login_status
    raise CheckLoginStatusExp(original_exception=ex) from ex
mypy.lib.playwright.exceptions.CheckLoginStatusExp: Page.inner_text: Timeout 120000ms exceeded.
Call log:
waiting for locator(".finder-nickname")

ERROR    mypy.lib.wechat.video.publish_app:publish_helper.py:171 üî¥ „Ääppt_video_maked„ÄãÂèëÂ∏ÉÂºÇÂ∏∏: Page.inner_text: Timeout 120000ms exceeded.
Call log:
waiting for locator(".finder-nickname")
Traceback (most recent call last):
  File "/home/runner/work/github-runner/github-runner/mypy/lib/playwright/core/publish_helper.py", line 94, in _check_login_status
    user_name = await self._get_logined_username(page)
  File "/home/runner/work/github-runner/github-runner/mypy/lib/playwright/core/publish_helper.py", line 85, in _get_logined_username
    raise ex
  File "/home/runner/work/github-runner/github-runner/mypy/lib/playwright/core/publish_helper.py", line 81, in _get_logined_username
    user_name = await page.inner_text(
  File "/opt/hostedtoolcache/Python/3.9.19/x64/lib/python3.9/site-packages/playwright/async_api/_generated.py", line 10493, in inner_text
    await self._impl_obj.inner_text(
  File "/opt/hostedtoolcache/Python/3.9.19/x64/lib/python3.9/site-packages/playwright/_impl/_page.py", line 904, in inner_text
    return await self._main_frame.inner_text(**locals_to_params(locals()))
  File "/opt/hostedtoolcache/Python/3.9.19/x64/lib/python3.9/site-packages/playwright/_impl/_frame.py", line 618, in inner_text
    return await self._channel.send("innerText", locals_to_params(locals()))
  File "/opt/hostedtoolcache/Python/3.9.19/x64/lib/python3.9/site-packages/playwright/_impl/_connection.py", line 59, in send
    return await self._connection.wrap_api_call(
  File "/opt/hostedtoolcache/Python/3.9.19/x64/lib/python3.9/site-packages/playwright/_impl/_connection.py", line 514, in wrap_api_call
    raise rewrite_error(error, f"{parsed_st['apiName']}: {error}") from None
playwright._impl._errors.TimeoutError: Page.inner_text: Timeout 120000ms exceeded.
Call log:
waiting for locator(".finder-nickname")


The above exception was the direct cause of the following exception:

Traceback (most recent call last):
  File "/home/runner/work/github-runner/github-runner/mypy/lib/playwright/core/publish_helper.py", line 169, in do_publish
    await self.publish_mission(playwright)
  File "/home/runner/work/github-runner/github-runner/mypy/utils/tools.py", line 454, in wrapper
    async for attempt in AsyncRetrying(
  File "/opt/hostedtoolcache/Python/3.9.19/x64/lib/python3.9/site-packages/tenacity/asyncio/__init__.py", line 166, in __anext__
    do = await self.iter(retry_state=self._retry_state)
  File "/opt/hostedtoolcache/Python/3.9.19/x64/lib/python3.9/site-packages/tenacity/asyncio/__init__.py", line 153, in iter
    result = await action(retry_state)
  File "/opt/hostedtoolcache/Python/3.9.19/x64/lib/python3.9/site-packages/tenacity/_utils.py", line 99, in inner
    return call(*args, **kwargs)
  File "/opt/hostedtoolcache/Python/3.9.19/x64/lib/python3.9/site-packages/tenacity/__init__.py", line 398, in <lambda>
    self._add_action_func(lambda rs: rs.outcome.result())
  File "/opt/hostedtoolcache/Python/3.9.19/x64/lib/python3.9/concurrent/futures/_base.py", line 439, in result
    return self.__get_result()
  File "/opt/hostedtoolcache/Python/3.9.19/x64/lib/python3.9/concurrent/futures/_base.py", line 391, in __get_result
    raise self._exception
  File "/home/runner/work/github-runner/github-runner/mypy/utils/tools.py", line 460, in wrapper
    await async_func(*args, **kwargs)
  File "/home/runner/work/github-runner/github-runner/mypy/lib/playwright/core/publish_helper.py", line 161, in publish_mission
    raise ex
  File "/home/runner/work/github-runner/github-runner/mypy/lib/playwright/core/publish_helper.py", line 145, in publish_mission
    await self._check_login_status(page)
  File "/home/runner/work/github-runner/github-runner/mypy/lib/playwright/core/publish_helper.py", line 98, in _check_login_status
    raise CheckLoginStatusExp(original_exception=ex) from ex
mypy.lib.playwright.exceptions.CheckLoginStatusExp: Page.inner_text: Timeout 120000ms exceeded.
Call log:
waiting for locator(".finder-nickname")