{"uid":"4f6576729e5852c3","name":"test_upd_channel_to_latest","fullName":"apps.youtu2douyin.test_youtu2douyin#test_upd_channel_to_latest","historyId":"46ba5f579826f915d5d6ff91ab40ae4c","time":{"start":1726827580839,"stop":1726827603930,"duration":23091},"description":"\n    更新频道记录的视频到最新\n    ","descriptionHtml":"<pre><code>更新频道记录的视频到最新\n</code></pre>\n","status":"broken","statusMessage":"tenacity.RetryError: RetryError[<Future at 0x7fa0140f2b20 state=finished raised PytubeError>]","statusTrace":"self = <pytube.__main__.YouTube object: videoId=phn0bXbcZYY>\n\n    @property\n    def title(self) -> str:\n        \"\"\"Get the video title.\n    \n        :rtype: str\n        \"\"\"\n        if self._title:\n            return self._title\n    \n        try:\n>           self._title = self.vid_info['videoDetails']['title']\nE           KeyError: 'videoDetails'\n\n/opt/hostedtoolcache/Python/3.9.20/x64/lib/python3.9/site-packages/pytube/__main__.py:341: KeyError\n\nDuring handling of the above exception, another exception occurred:\n\nself = <Retrying object at 0x7fa0140f2910 (stop=<tenacity.stop.stop_after_attempt object at 0x7fa016540f40>, wait=<tenacity.w...0x7fa016540ee0>, before=<function before_nothing at 0x7fa045fcaee0>, after=<function after_nothing at 0x7fa045fd4280>)>\nfn = <function get_new_video_info at 0x7fa016566550>\nargs = (<pytube.__main__.YouTube object: videoId=phn0bXbcZYY>,), kwargs = {}\nretry_state = <RetryCallState 140325508032928: attempt #5; slept for 12.0; last result: failed (PytubeError Exception while accessing title of https://youtube.com/watch?v=phn0bXbcZYY. Please file a bug report at https://github.com/pytube/pytube)>\ndo = <tenacity.DoAttempt object at 0x7fa0140f21f0>\n\n    def __call__(\n        self,\n        fn: t.Callable[..., WrappedFnReturnT],\n        *args: t.Any,\n        **kwargs: t.Any,\n    ) -> WrappedFnReturnT:\n        self.begin()\n    \n        retry_state = RetryCallState(retry_object=self, fn=fn, args=args, kwargs=kwargs)\n        while True:\n            do = self.iter(retry_state=retry_state)\n            if isinstance(do, DoAttempt):\n                try:\n>                   result = fn(*args, **kwargs)\n\n/opt/hostedtoolcache/Python/3.9.20/x64/lib/python3.9/site-packages/tenacity/__init__.py:478: \n_ _ _ _ _ _ _ _ _ _ _ _ _ _ _ _ _ _ _ _ _ _ _ _ _ _ _ _ _ _ _ _ _ _ _ _ _ _ _ _ \nmypy/apps/youtu2douyin/tools.py:79: in get_new_video_info\n    new_video.title, new_video.video_id, new_video.publish_date)\n_ _ _ _ _ _ _ _ _ _ _ _ _ _ _ _ _ _ _ _ _ _ _ _ _ _ _ _ _ _ _ _ _ _ _ _ _ _ _ _ \n\nself = <pytube.__main__.YouTube object: videoId=phn0bXbcZYY>\n\n    @property\n    def title(self) -> str:\n        \"\"\"Get the video title.\n    \n        :rtype: str\n        \"\"\"\n        if self._title:\n            return self._title\n    \n        try:\n            self._title = self.vid_info['videoDetails']['title']\n        except KeyError:\n            # Check_availability will raise the correct exception in most cases\n            #  if it doesn't, ask for a report.\n            self.check_availability()\n>           raise exceptions.PytubeError(\n                (\n                    f'Exception while accessing title of {self.watch_url}. '\n                    'Please file a bug report at https://github.com/pytube/pytube'\n                )\n            )\nE           pytube.exceptions.PytubeError: Exception while accessing title of https://youtube.com/watch?v=phn0bXbcZYY. Please file a bug report at https://github.com/pytube/pytube\n\n/opt/hostedtoolcache/Python/3.9.20/x64/lib/python3.9/site-packages/pytube/__main__.py:346: PytubeError\n\nThe above exception was the direct cause of the following exception:\n\n    def test_upd_channel_to_latest():\n        \"\"\"\n        更新频道记录的视频到最新\n        \"\"\"\n        record_file_dir = os.path.join(curr_dir, 'config')\n        last_n = 2\n    \n        coll_handler = YouTubeChannel\n>       upd_channel_to_latest(record_file_dir=record_file_dir,\n                              coll_handler=coll_handler,\n                              last_n=last_n)\n\nmypy/tests/apps/youtu2douyin/test_youtu2douyin.py:48: \n_ _ _ _ _ _ _ _ _ _ _ _ _ _ _ _ _ _ _ _ _ _ _ _ _ _ _ _ _ _ _ _ _ _ _ _ _ _ _ _ \nmypy/apps/youtu2douyin/tools.py:108: in upd_channel_to_latest\n    item['videos'] = [\nmypy/apps/youtu2douyin/tools.py:109: in <listcomp>\n    get_new_video_info(item)\n/opt/hostedtoolcache/Python/3.9.20/x64/lib/python3.9/site-packages/tenacity/__init__.py:336: in wrapped_f\n    return copy(f, *args, **kw)\n/opt/hostedtoolcache/Python/3.9.20/x64/lib/python3.9/site-packages/tenacity/__init__.py:475: in __call__\n    do = self.iter(retry_state=retry_state)\n/opt/hostedtoolcache/Python/3.9.20/x64/lib/python3.9/site-packages/tenacity/__init__.py:376: in iter\n    result = action(retry_state)\n_ _ _ _ _ _ _ _ _ _ _ _ _ _ _ _ _ _ _ _ _ _ _ _ _ _ _ _ _ _ _ _ _ _ _ _ _ _ _ _ \n\nrs = <RetryCallState 140325508032928: attempt #5; slept for 12.0; last result: failed (PytubeError Exception while accessing title of https://youtube.com/watch?v=phn0bXbcZYY. Please file a bug report at https://github.com/pytube/pytube)>\n\n    def exc_check(rs: \"RetryCallState\") -> None:\n        fut = t.cast(Future, rs.outcome)\n        retry_exc = self.retry_error_cls(fut)\n        if self.reraise:\n            raise retry_exc.reraise()\n>       raise retry_exc from fut.exception()\nE       tenacity.RetryError: RetryError[<Future at 0x7fa0140f2b20 state=finished raised PytubeError>]\n\n/opt/hostedtoolcache/Python/3.9.20/x64/lib/python3.9/site-packages/tenacity/__init__.py:419: RetryError","flaky":false,"newFailed":false,"newBroken":false,"newPassed":false,"retriesCount":0,"retriesStatusChange":false,"beforeStages":[{"name":"event_loop_policy","time":{"start":1726825585676,"stop":1726825585676,"duration":0},"status":"passed","steps":[],"attachments":[],"parameters":[],"shouldDisplayMessage":false,"stepsCount":0,"attachmentsCount":0,"hasContent":false,"attachmentStep":false},{"name":"copy_config_to_dir","time":{"start":1726827576456,"stop":1726827576457,"duration":1},"status":"passed","steps":[],"attachments":[],"parameters":[],"shouldDisplayMessage":false,"stepsCount":0,"attachmentsCount":0,"hasContent":false,"attachmentStep":false}],"testStage":{"description":"\n    更新频道记录的视频到最新\n    ","status":"broken","statusMessage":"tenacity.RetryError: RetryError[<Future at 0x7fa0140f2b20 state=finished raised PytubeError>]","statusTrace":"self = <pytube.__main__.YouTube object: videoId=phn0bXbcZYY>\n\n    @property\n    def title(self) -> str:\n        \"\"\"Get the video title.\n    \n        :rtype: str\n        \"\"\"\n        if self._title:\n            return self._title\n    \n        try:\n>           self._title = self.vid_info['videoDetails']['title']\nE           KeyError: 'videoDetails'\n\n/opt/hostedtoolcache/Python/3.9.20/x64/lib/python3.9/site-packages/pytube/__main__.py:341: KeyError\n\nDuring handling of the above exception, another exception occurred:\n\nself = <Retrying object at 0x7fa0140f2910 (stop=<tenacity.stop.stop_after_attempt object at 0x7fa016540f40>, wait=<tenacity.w...0x7fa016540ee0>, before=<function before_nothing at 0x7fa045fcaee0>, after=<function after_nothing at 0x7fa045fd4280>)>\nfn = <function get_new_video_info at 0x7fa016566550>\nargs = (<pytube.__main__.YouTube object: videoId=phn0bXbcZYY>,), kwargs = {}\nretry_state = <RetryCallState 140325508032928: attempt #5; slept for 12.0; last result: failed (PytubeError Exception while accessing title of https://youtube.com/watch?v=phn0bXbcZYY. Please file a bug report at https://github.com/pytube/pytube)>\ndo = <tenacity.DoAttempt object at 0x7fa0140f21f0>\n\n    def __call__(\n        self,\n        fn: t.Callable[..., WrappedFnReturnT],\n        *args: t.Any,\n        **kwargs: t.Any,\n    ) -> WrappedFnReturnT:\n        self.begin()\n    \n        retry_state = RetryCallState(retry_object=self, fn=fn, args=args, kwargs=kwargs)\n        while True:\n            do = self.iter(retry_state=retry_state)\n            if isinstance(do, DoAttempt):\n                try:\n>                   result = fn(*args, **kwargs)\n\n/opt/hostedtoolcache/Python/3.9.20/x64/lib/python3.9/site-packages/tenacity/__init__.py:478: \n_ _ _ _ _ _ _ _ _ _ _ _ _ _ _ _ _ _ _ _ _ _ _ _ _ _ _ _ _ _ _ _ _ _ _ _ _ _ _ _ \nmypy/apps/youtu2douyin/tools.py:79: in get_new_video_info\n    new_video.title, new_video.video_id, new_video.publish_date)\n_ _ _ _ _ _ _ _ _ _ _ _ _ _ _ _ _ _ _ _ _ _ _ _ _ _ _ _ _ _ _ _ _ _ _ _ _ _ _ _ \n\nself = <pytube.__main__.YouTube object: videoId=phn0bXbcZYY>\n\n    @property\n    def title(self) -> str:\n        \"\"\"Get the video title.\n    \n        :rtype: str\n        \"\"\"\n        if self._title:\n            return self._title\n    \n        try:\n            self._title = self.vid_info['videoDetails']['title']\n        except KeyError:\n            # Check_availability will raise the correct exception in most cases\n            #  if it doesn't, ask for a report.\n            self.check_availability()\n>           raise exceptions.PytubeError(\n                (\n                    f'Exception while accessing title of {self.watch_url}. '\n                    'Please file a bug report at https://github.com/pytube/pytube'\n                )\n            )\nE           pytube.exceptions.PytubeError: Exception while accessing title of https://youtube.com/watch?v=phn0bXbcZYY. Please file a bug report at https://github.com/pytube/pytube\n\n/opt/hostedtoolcache/Python/3.9.20/x64/lib/python3.9/site-packages/pytube/__main__.py:346: PytubeError\n\nThe above exception was the direct cause of the following exception:\n\n    def test_upd_channel_to_latest():\n        \"\"\"\n        更新频道记录的视频到最新\n        \"\"\"\n        record_file_dir = os.path.join(curr_dir, 'config')\n        last_n = 2\n    \n        coll_handler = YouTubeChannel\n>       upd_channel_to_latest(record_file_dir=record_file_dir,\n                              coll_handler=coll_handler,\n                              last_n=last_n)\n\nmypy/tests/apps/youtu2douyin/test_youtu2douyin.py:48: \n_ _ _ _ _ _ _ _ _ _ _ _ _ _ _ _ _ _ _ _ _ _ _ _ _ _ _ _ _ _ _ _ _ _ _ _ _ _ _ _ \nmypy/apps/youtu2douyin/tools.py:108: in upd_channel_to_latest\n    item['videos'] = [\nmypy/apps/youtu2douyin/tools.py:109: in <listcomp>\n    get_new_video_info(item)\n/opt/hostedtoolcache/Python/3.9.20/x64/lib/python3.9/site-packages/tenacity/__init__.py:336: in wrapped_f\n    return copy(f, *args, **kw)\n/opt/hostedtoolcache/Python/3.9.20/x64/lib/python3.9/site-packages/tenacity/__init__.py:475: in __call__\n    do = self.iter(retry_state=retry_state)\n/opt/hostedtoolcache/Python/3.9.20/x64/lib/python3.9/site-packages/tenacity/__init__.py:376: in iter\n    result = action(retry_state)\n_ _ _ _ _ _ _ _ _ _ _ _ _ _ _ _ _ _ _ _ _ _ _ _ _ _ _ _ _ _ _ _ _ _ _ _ _ _ _ _ \n\nrs = <RetryCallState 140325508032928: attempt #5; slept for 12.0; last result: failed (PytubeError Exception while accessing title of https://youtube.com/watch?v=phn0bXbcZYY. Please file a bug report at https://github.com/pytube/pytube)>\n\n    def exc_check(rs: \"RetryCallState\") -> None:\n        fut = t.cast(Future, rs.outcome)\n        retry_exc = self.retry_error_cls(fut)\n        if self.reraise:\n            raise retry_exc.reraise()\n>       raise retry_exc from fut.exception()\nE       tenacity.RetryError: RetryError[<Future at 0x7fa0140f2b20 state=finished raised PytubeError>]\n\n/opt/hostedtoolcache/Python/3.9.20/x64/lib/python3.9/site-packages/tenacity/__init__.py:419: RetryError","steps":[],"attachments":[{"uid":"5a808f4da71c92e6","name":"log","source":"5a808f4da71c92e6.txt","type":"text/plain","size":1369}],"parameters":[],"shouldDisplayMessage":true,"stepsCount":0,"attachmentsCount":1,"hasContent":true,"attachmentStep":false},"afterStages":[{"name":"copy_config_to_dir::finish_callback","time":{"start":1726827628203,"stop":1726827628204,"duration":1},"status":"passed","steps":[],"attachments":[],"parameters":[],"shouldDisplayMessage":false,"stepsCount":0,"attachmentsCount":0,"hasContent":false,"attachmentStep":false}],"labels":[{"name":"tag","value":"app"},{"name":"parentSuite","value":"apps.youtu2douyin"},{"name":"suite","value":"test_youtu2douyin"},{"name":"host","value":"fv-az654-555"},{"name":"thread","value":"9906-MainThread"},{"name":"framework","value":"pytest"},{"name":"language","value":"cpython3"},{"name":"package","value":"apps.youtu2douyin.test_youtu2douyin"},{"name":"resultFormat","value":"allure2"}],"parameters":[],"links":[],"hidden":false,"retry":false,"extra":{"severity":"normal","retries":[],"categories":[{"name":"Test defects","matchedStatuses":[],"flaky":false}],"tags":["app"]},"source":"4f6576729e5852c3.json","parameterValues":[]}